Workbook

Sheet Cmg_Barra
B3: S/./MWh | C3: AGUAYTIA 13.8 | D3: AGUAYTIA 138 | E3: AGUAYTIA 22.9 | F3: AGUAYTIA 220 | G3: ALTO PRADERAS 220kV | H3: ARICOTA1 66 | I3: ARICOTA2 138 | J3: ARICOTA66 | K3: ASIA 220 | L3: AUCAYACU 138 | M3: AYAVIRI 138 | N3: AZANGARO 138 | O3: BELAUNDE 138 | P3: BOTIFLACA 138 | Q3: CACHIMAYO 138 | R3: CAHUA 10 | S3: CAHUA138 | T3: CAJAMARCA 220 | U3: CAJAMARQUILLA 220 | V3: CALLAHUANCA 60 | W3: CALLAHUANCA EDEGEL 220 | X3: CALLALLI 138 | Y3: CAMPO ARMIÑO 220 | Z3: CANTERA 220 | AA3: CARABAYLLO 220 | AB3: CARHUAMAYO 138 | AC3: CARHUAQUE10 | AD3: CARHUAQUERO 220 | AE3: CARIPA138 | AF3: CATKATO4.16 | AG3: CCORONA220 | AH3: CERRO DEL AGUILA 13.8 | AI3: CERRO DEL AGUILA 220 | AJ3: CERRO VERDE 138 | AK3: CH OROYA 50 | AL3: CHAGLLA 220 | AM3: CHARCANI I 33 | AN3: CHARCANI IV 33 | AO3: CHARCANI VI 33 | AP3: CHAVARRIA 220 | AQ3: CHEVES 220 | AR3: CHICLAYO 220 | AS3: CHILCA DOS 13.8 | AT3: CHILCA REP 220 | AU3: CHILCA UNO 220 | AV3: CHILCA500 | AW3: CHILCACTM220 | AX3: CHILCAI16 | AY3: CHILID10.5 | AZ3: CHILINA 138 | BA3: CHILINA 33 | BB3: CHILITG13.8 | BC3: CHIMAY220 | BD3: CHIMBOTE1 138 | BE3: CHIMBOTE1 220 | BF3: COMBAPATA 138 | BG3: CONDORCOCHA 138 | BH3: CONDORCOCHA 44 | BI3: COTARUSE 220 | BJ3: CPATO13.8 | BK3: CT ETEN 220 | BL3: CT INDEPENDENCIA 60 | BM3: CT PISCO 60 | BN3: CT PLANTA PUCALLPA 60 | BO3: CTILO217 | BP3: CUTERVO 138 | BQ3: DESIERTO 220 | BR3: DOLORESPATA 10.5 | BS3: DOLORESPATA 138 | BT3: ETEN 18 | BU3: FENIX 500 | BV3: FENIX18 | BW3: GALLITO CIEGO 60 | BX3: GUADALUPE 220 | BY3: GUADALUPE 60 | BZ3: HUACHO 220 | CA3: HUALLANCA 138 | CB3: HUAMPANI 60 | CC3: HUANCAVELICA 220 | CD3: HUANCHOR50 | CE3: HUANUCO 138 | CF3: HUANZA 220 | CG3: HUAYLLACHO 15 | CH3: HUAYUCACHI 220 | CI3: HUINCO 220 | CJ3: HUINCO12.5 | CK3: ICA 220 | CL3: ILO ELP 138 | CM3: ILO1 138 | CN3: ILO2 220 | CO3: ILO4-18 | CP3: ILOTG1 | CQ3: INDEPENDENCIA 220 | CR3: INDEPENDENCIA 60 | CS3: INDUSTRIALES 220 | CT3: JULIACA 138 | CU3: JULIACA10 | CV3: KALLPA16.5 | CW3: LA NIÑA 220 | CX3: LA RAMADA 220 | CY3: LANIÑA500 | CZ3: LAS FLORES 220 | DA3: LFLORES16.5 | DB3: LOMERA 220 | DC3: LOS HEROES 220 | DD3: LOS HEROES 66 | DE3: MACHUPICCHU 138 | DF3: MALPASO 50 | DG3: MALPASO6.9 | DH3: MARAÑON 60 | DI3: MARCONA 220 | DJ3: MATUCANA 220 | DK3: MATUCANA 12.5 | DL3: MAZUCO138 | DM3: MISAPUQUIO 33 | DN3: MOLLENDO 138 | DO3: MOLLENDO13.8 | DP3: MONTALVO220 | DQ3: MOQUEGUA 138 | DR3: MOYOPAMPA 60 | DS3: NCTUMBES60 | DT3: OLLEROS 500 | DU3: OLLEROS16.5 | DV3: OQUENDO60 | DW3: OROYA NUEVA 50 | DX3: OROYA220 | DY3: PACHACHACA 220 | DZ3: PACHACHACA50 | EA3: PARAGSHA2 138 | EB3: PARAGSHA2 220 | EC3: PARAMONGA EXISTENTE 138 | ED3: PARAMONGA NUEVA 138 | EE3: PARAMONGA NUEVA 220 | EF3: PARIAC 66 | EG3: PIEDRA BLANCA 34.5 kV | EH3: PIURA OESTE 220 | EI3: PLANICIE220 | EJ3: PLANTAETANOL 60 | EK3: PLATANAL13.8 | EL3: PLATANAL220 | EM3: POMACOCHA 220 | EN3: POROMA 220 | EO3: PUCALLPA 0.5 | EP3: PUCALLPA 60 | EQ3: PUERTO BRAVO 18 | ER3: PUERTO BRAVO 500 | ES3: PUERTO MALDONADO 0.5 | ET3: PUERTO MALDONADO 10 | EU3: PUNO 138 | EV3: QUENCORO 138 | EW3: QUITARACSA 220 | EX3: RECKA 220 | EY3: RECKA18 | EZ3: REPARTICIÓN 138 | FA3: RESTITUCIÓN 220 | FB3: S.E. ILO4 500 | FC3: SAN ANTONIO 15 | FD3: SAN GABAN 138 | FE3: SAN IGNACIO 15 | FF3: SAN JOSÉ 500 kV | FG3: SAN JUAN 220 | FH3: SAN NICOLAS 13.8 | FI3: SANTA ISABEL 220 | FJ3: SANTA ROSA 220 | FK3: SANTA TERESA 220 | FL3: SANTUARIO 138 | FM3: SOCABAYA 138 | FN3: SOCABAYA 220 | FO3: SROSATG7 | FP3: SROSATG8 | FQ3: SROSAUTI | FR3: TABLAZO 13.8 | FS3: TABLAZO 60 | FT3: TALARA 220 | FU3: TALARA13.2 | FV3: TALARA13.8 | FW3: TG5_16.5 | FX3: TINGO MARIA 138 | FY3: TINTAYA EXISTENTE 138 | FZ3: TINTAYA NUEVA 220 | GA3: TOCACHE 138 | GB3: TOQUEPALA 138 | GC3: TRUJILLO 220 | GD3: VENTANILLA 220 | GE3: VENTANILLA16 | GF3: VIZCARRA 220 | GG3: YANANGO220 | GH3: YAUPI13.8 | GI3: YAUPI138 | GJ3: ZAPALLAL 220 | GK3: ZORRITOS 220
B4: 43431.021 | C4: 23.861898 | D4: 23.89229 | E4: 23.880124 | F4: 23.861874 | G4: 24.246491 | H4: 25.796297 | I4: 25.89315 | J4: 25.844628 | K4: 24.554994 | L4: 23.950037 | M4: 25.589656 | N4: 25.062045 | O4: 24.213224 | P4: 25.864525 | Q4: 24.332817 | R4: 23.387597 | S4: 23.418455 | T4: 23.95427 | U4: 24.138377 | V4: 23.865533 | W4: 23.794142 | X4: 26.465406 | Y4: 22.904412 | Z4: 24.523938 | AA4: 24.134263 | AB4: 22.41349 | AC4: 23.756692 | AD4: 23.91471 | AE4: 22.542232 | AF4: 25.992736 | AG4: 24.012194 | AH4: 23.140634 | AI4: 23.218515 | AJ4: 25.754283 | AK4: 22.562555 | AL4: 21.119863 | AM4: 24.825033 | AN4: 24.223851 | AO4: 24.954694 | AP4: 24.214909 | AQ4: 23.328671 | AR4: 24.617597 | AS4: 23.914961 | AT4: 24.113659 | AU4: 23.987799 | AV4: 23.972983 | AW4: 23.997654 | AX4: 23.954079 | AY4: 25.768734 | AZ4: 25.82927 | BA4: 25.768533 | BB4: 25.768598 | BC4: 22.153706 | BD4: 24.216187 | BE4: 24.210457 | BF4: 25.46027 | BG4: 22.546694 | BH4: 22.546694 | BI4: 24.412386 | BJ4: 23.048716 | BK4: 24.596684 | BL4: 24.464125 | BM4: 24.464125 | BN4: 24.946697 | BO4: 25.563895 | BP4: 23.879412 | BQ4: 24.374632 | BR4: 24.539879 | BS4: 24.463566 | BT4: 24.596684 | BU4: 23.972983 | BV4: 23.872002 | BW4: 24.11063 | BX4: 24.482164 | BY4: 24.485502 | BZ4: 23.804341 | CA4: 23.121919 | CB4: 23.865533 | CC4: 23.334808 | CD4: 27.582272 | CE4: 22.704457 | CF4: 23.723757 | CG4: 28.059364 | CH4: 23.142498 | CI4: 24.010085 | CJ4: 23.978178 | CK4: 24.45795 | CL4: 25.905133 | CM4: 25.992535 | CN4: 25.551539 | CO4: 25.361753 | CP4: 25.992577 | CQ4: 24.366547 | CR4: 24.464125 | CS4: 24.224222 | CT4: 25.424916 | CU4: 25.444101 | CV4: 24.113664 | CW4: 24.399708 | CX4: 23.662753 | CY4: 24.392196 | CZ4: 23.997654 | DA4: 23.997654 | DB4: 24.016636 | DC4: 25.811164 | DD4: 25.929962 | DE4: 23.212776 | DF4: 21.587409 | DG4: 21.540057 | DH4: 21.750746 | DI4: 24.586129 | DJ4: 23.757193 | DK4: 23.716502 | DL4: 22.985819 | DM4: 27.408263 | DN4: 26.064321 | DO4: 26.06437 | DP4: 25.499007 | DQ4: 25.551539 | DR4: 23.865533 | DS4: 26.2241 | DT4: 23.972983 | DU4: 23.890562 | DV4: 24.109396 | DW4: 22.737271 | DX4: 22.722625 | DY4: 23.318814 | DZ4: 23.444305 | EA4: 22.515419 | EB4: 22.388917 | EC4: 23.952515 | ED4: 23.835285 | EE4: 23.786443 | EF4: 24.942608 | EG4: 22.538348 | EH4: 25.84528 | EI4: 24.211149 | EJ4: 26.712419 | EK4: 23.996152 | EL4: 23.996152 | EM4: 23.430912 | EN4: 24.528024 | EO4: 24.946697 | EP4: 24.946697 | EQ4: 25.316683 | ER4: 25.316192 | ES4: 23.667843 | ET4: 23.667843 | EU4: 25.440594 | EV4: 24.491637 | EW4: 23.364424 | EX4: 24.596684 | EY4: 24.596684 | EZ4: 25.913815 | FA4: 22.89672 | FB4: 25.361753 | FC4: 28.058967 | FD4: 22.7022 | FE4: 28.058967 | FF4: 25.315037 | FG4: 24.23284 | FH4: 25.170621 | FI4: 22.181572 | FJ4: 24.221569 | FK4: 23.491976 | FL4: 25.783523 | FM4: 25.655034 | FN4: 25.600764 | FO4: 24.221589 | FP4: 24.221569 | FQ4: 24.221581 | FR4: 26.442304 | FS4: 26.442304 | FT4: 25.342764 | FU4: 25.364833 | FV4: 25.275813 | FW4: 25.941635 | FX4: 23.757712 | FY4: 26.476473 | FZ4: 26.451704 | GA4: 24.359149 | GB4: 25.960381 | GC4: 24.34893 | GD4: 24.143233 | GE4: 24.09222 | GF4: 23.304329 | GG4: 22.397533 | GH4: 21.657714 | GI4: 21.729007 | GJ4: 24.132034 | GK4: 26.185841
B5: 43431.042 | C5: 23.903665 | D5: 23.933325 | E5: 23.921452 | F5: 23.903641 | G5: 24.334817 | H5: 25.993092 | I5: 26.078277 | J5: 26.033219 | K5: 24.916236 | L5: 23.995712 | M5: 25.746298 | N5: 25.213578 | O5: 24.23517 | P5: 26.043373 | Q5: 24.444318 | R5: 23.41454 | S5: 23.446686 | T5: 23.995322 | U5: 24.21034 | V5: 23.938726 | W5: 23.872175 | X5: 26.631904 | Y5: 23.042424 | Z5: 24.898164 | AA5: 24.214269 | AB5: 22.462636 | AC5: 23.793941 | AD5: 23.950599 | AE5: 22.594041 | AF5: 26.156217 | AG5: 24.055649 | AH5: 23.246685 | AI5: 23.332591 | AJ5: 25.919491 | AK5: 22.620606 | AL5: 21.139694 | AM5: 25.107215 | AN5: 24.595523 | AO5: 25.226474 | AP5: 24.283147 | AQ5: 23.394824 | AR5: 24.641804 | AS5: 24.00906 | AT5: 24.214455 | AU5: 24.082085 | AV5: 24.064177 | AW5: 24.09184 | AX5: 24.0488 | AY5: 25.966067 | AZ5: 26.007897 | BA5: 25.965866 | BB5: 25.965931 | BC5: 22.267801 | BD5: 24.270084 | BE5: 24.265742 | BF5: 25.586363 | BG5: 22.598227 | BH5: 22.598227 | BI5: 24.561637 | BJ5: 23.072897 | BK5: 24.622518 | BL5: 24.861965 | BM5: 24.861965 | BN5: 24.954352 | BO5: 25.727208 | BP5: 23.915248 | BQ5: 24.661832 | BR5: 24.638329 | BS5: 24.567173 | BT5: 24.622518 | BU5: 24.064177 | BV5: 23.962952 | BW5: 24.129193 | BX5: 24.516913 | BY5: 24.520176 | BZ5: 23.868358 | CA5: 23.148372 | CB5: 23.938726 | CC5: 23.541861 | CD5: 27.589963 | CE5: 22.734982 | CF5: 23.935434 | CG5: 28.23589 | CH5: 23.301683 | CI5: 24.072894 | CJ5: 24.036594 | CK5: 24.81549 | CL5: 26.068887 | CM5: 26.156313 | CN5: 25.713555 | CO5: 25.520731 | CP5: 26.156356 | CQ5: 24.765322 | CR5: 24.861965 | CS5: 24.296854 | CT5: 25.574351 | CU5: 25.593565 | CV5: 24.21446 | CW5: 24.44599 | CX5: 23.704977 | CY5: 24.439255 | CZ5: 24.09184 | DA5: 24.09184 | DB5: 24.085129 | DC5: 25.969704 | DD5: 26.084098 | DE5: 23.352343 | DF5: 21.644064 | DG5: 21.59659 | DH5: 21.793225 | DI5: 24.748069 | DJ5: 23.825835 | DK5: 23.786217 | DL5: 23.117996 | DM5: 27.580692 | DN5: 26.23668 | DO5: 26.236729 | DP5: 25.659582 | DQ5: 25.713555 | DR5: 23.938726 | DS5: 26.17082 | DT5: 24.064177 | DU5: 23.981453 | DV5: 24.17424 | DW5: 22.795625 | DX5: 22.783035 | DY5: 23.414941 | DZ5: 23.450842 | EA5: 22.567614 | EB5: 22.436852 | EC5: 24.002945 | ED5: 23.890762 | EE5: 23.844025 | EF5: 24.971144 | EG5: 22.570845 | EH5: 25.797873 | EI5: 24.286654 | EJ5: 26.64624 | EK5: 24.214455 | EL5: 24.214455 | EM5: 23.525932 | EN5: 24.671097 | EO5: 24.954352 | EP5: 24.954352 | EQ5: 25.471291 | ER5: 25.470798 | ES5: 23.780123 | ET5: 23.780123 | EU5: 25.59186 | EV5: 24.593694 | EW5: 23.401741 | EX5: 24.622518 | EY5: 24.622518 | EZ5: 26.077676 | FA5: 23.034774 | FB5: 25.520731 | FC5: 28.235491 | FD5: 22.848703 | FE5: 28.235491 | FF5: 25.46964 | FG5: 24.314112 | FH5: 25.332825 | FI5: 22.227217 | FJ5: 24.291342 | FK5: 23.633469 | FL5: 25.952711 | FM5: 25.820522 | FN5: 25.765354 | FO5: 24.291362 | FP5: 24.291342 | FQ5: 24.291355 | FR5: 26.32403 | FS5: 26.32403 | FT5: 25.291738 | FU5: 25.313586 | FV5: 25.224507 | FW5: 25.891931 | FX5: 23.804189 | FY5: 26.643462 | FZ5: 26.620068 | GA5: 24.368722 | GB5: 26.140053 | GC5: 24.397796 | GD5: 24.212826 | GE5: 24.161663 | GF5: 23.349842 | GG5: 22.512588 | GH5: 21.697895 | GI5: 21.770111 | GJ5: 24.209609 | GK5: 26.133046
B6: 43431.063 | C6: 23.832237 | D6: 23.86143 | E6: 23.849743 | F6: 23.832213 | G6: 24.213197 | H6: 25.818408 | I6: 25.893843 | J6: 25.851542 | K6: 24.559457 | L6: 23.909965 | M6: 25.533833 | N6: 25.00864 | O6: 24.176054 | P6: 25.850692 | Q6: 24.289454 | R6: 23.396377 | S6: 23.426246 | T6: 23.9411 | U6: 24.108789 | V6: 23.850938 | W6: 23.775286 | X6: 26.418229 | Y6: 22.898171 | Z6: 24.535212 | AA6: 24.107447 | AB6: 22.427103 | AC6: 23.729425 | AD6: 23.886 | AE6: 22.550604 | AF6: 25.965185 | AG6: 24.000773 | AH6: 23.09609 | AI6: 23.182484 | AJ6: 25.726268 | AK6: 22.565323 | AL6: 21.156265 | AM6: 24.900597 | AN6: 24.385732 | AO6: 25.05207 | AP6: 24.1764 | AQ6: 23.334227 | AR6: 24.564036 | AS6: 23.89412 | AT6: 24.092319 | AU6: 23.966966 | AV6: 23.950627 | AW6: 23.976336 | AX6: 23.935258 | AY6: 25.761844 | AZ6: 25.807884 | BA6: 25.761644 | BB6: 25.761709 | BC6: 22.167331 | BD6: 24.189418 | BE6: 24.182684 | BF6: 25.396532 | BG6: 22.555948 | BH6: 22.555948 | BI6: 24.400434 | BJ6: 23.06054 | BK6: 24.545927 | BL6: 24.48556 | BM6: 24.48556 | BN6: 24.872571 | BO6: 25.540157 | BP6: 23.850744 | BQ6: 24.390504 | BR6: 24.478495 | BS6: 24.408878 | BT6: 24.545927 | BU6: 23.950627 | BV6: 23.850441 | BW6: 24.041484 | BX6: 24.446792 | BY6: 24.449567 | BZ6: 23.790715 | CA6: 23.132745 | CB6: 23.850938 | CC6: 23.332248 | CD6: 27.534921 | CE6: 22.688863 | CF6: 23.819739 | CG6: 28.009346 | CH6: 23.165932 | CI6: 24.004117 | CJ6: 23.981378 | CK6: 24.474985 | CL6: 25.878075 | CM6: 25.964965 | CN6: 25.527966 | CO6: 25.34075 | CP6: 25.965007 | CQ6: 24.38859 | CR6: 24.48556 | CS6: 24.185122 | CT6: 25.368372 | CU6: 25.386547 | CV6: 24.092324 | CW6: 24.364402 | CX6: 23.665616 | CY6: 24.357238 | CZ6: 23.976336 | DA6: 23.976336 | DB6: 23.992009 | DC6: 25.778497 | DD6: 25.88954 | DE6: 23.212814 | DF6: 21.591601 | DG6: 21.545729 | DH6: 21.746815 | DI6: 24.580932 | DJ6: 23.745202 | DK6: 23.708141 | DL6: 22.929045 | DM6: 27.359405 | DN6: 26.018215 | DO6: 26.018264 | DP6: 25.47565 | DQ6: 25.527966 | DR6: 23.798716 | DS6: 26.017786 | DT6: 23.950627 | DU6: 23.868004 | DV6: 24.066834 | DW6: 22.739489 | DX6: 22.727 | DY6: 23.307049 | DZ6: 23.404058 | EA6: 22.534258 | EB6: 22.405277 | EC6: 23.943266 | ED6: 23.823956 | EE6: 23.774246 | EF6: 24.954287 | EG6: 22.525342 | EH6: 25.674628 | EI6: 24.173888 | EJ6: 26.516085 | EK6: 24.092319 | EL6: 24.092319 | EM6: 23.41697 | EN6: 24.512226 | EO6: 24.872571 | EP6: 24.872571 | EQ6: 25.293848 | ER6: 25.293396 | ES6: 23.56786 | ET6: 23.56786 | EU6: 25.390724 | EV6: 24.434424 | EW6: 23.387019 | EX6: 24.545927 | EY6: 24.545927 | EZ6: 25.865427 | FA6: 22.890539 | FB6: 25.34075 | FC6: 28.00895 | FD6: 22.671068 | FE6: 28.00895 | FF6: 25.292334 | FG6: 24.193321 | FH6: 25.179601 | FI6: 22.199984 | FJ6: 24.182612 | FK6: 23.486772 | FL6: 25.756276 | FM6: 25.632113 | FN6: 25.578821 | FO6: 24.182631 | FP6: 24.182612 | FQ6: 24.182624 | FR6: 26.280347 | FS6: 26.280347 | FT6: 25.16825 | FU6: 25.189449 | FV6: 25.101342 | FW6: 25.74235 | FX6: 23.731662 | FY6: 26.420709 | FZ6: 26.396286 | GA6: 24.268378 | GB6: 25.947912 | GC6: 24.315781 | GD6: 24.109408 | GE6: 24.061137 | GF6: 23.300117 | GG6: 22.404575 | GH6: 21.668216 | GI6: 21.740847 | GJ6: 24.103924 | GK6: 25.98048
B7: 43431.083 | C7: 23.777507 | D7: 23.804742 | E7: 23.793839 | F7: 23.777484 | G7: 24.205492 | H7: 25.698443 | I7: 25.780894 | J7: 25.736194 | K7: 24.77254 | L7: 23.851222 | M7: 25.442093 | N7: 24.914509 | O7: 24.120968 | P7: 25.767737 | Q7: 24.155017 | R7: 23.382882 | S7: 23.411925 | T7: 23.889705 | U7: 24.109919 | V7: 23.859118 | W7: 23.779293 | X7: 26.343318 | Y7: 22.90821 | Z7: 24.73238 | AA7: 24.096734 | AB7: 22.386261 | AC7: 23.663826 | AD7: 23.822075 | AE7: 22.520081 | AF7: 25.878676 | AG7: 23.949051 | AH7: 23.116334 | AI7: 23.19698 | AJ7: 25.650143 | AK7: 22.544312 | AL7: 21.143756 | AM7: 24.809608 | AN7: 24.291069 | AO7: 24.965125 | AP7: 24.173447 | AQ7: 23.295461 | AR7: 24.481115 | AS7: 23.887577 | AT7: 24.088664 | AU7: 23.960356 | AV7: 23.941391 | AW7: 23.969646 | AX7: 23.928972 | AY7: 25.674238 | AZ7: 25.727049 | BA7: 25.674038 | BB7: 25.674103 | BC7: 22.188401 | BD7: 24.152311 | BE7: 24.147116 | BF7: 25.282863 | BG7: 22.523266 | BH7: 22.523266 | BI7: 24.282857 | BJ7: 23.04023 | BK7: 24.463893 | BL7: 24.66647 | BM7: 24.66647 | BN7: 24.746595 | BO7: 25.472005 | BP7: 23.786914 | BQ7: 24.498613 | BR7: 24.344384 | BS7: 24.276259 | BT7: 24.463893 | BU7: 23.941391 | BV7: 23.839968 | BW7: 23.932983 | BX7: 24.369637 | BY7: 24.370806 | BZ7: 23.764176 | CA7: 23.111199 | CB7: 23.859118 | CC7: 23.386365 | CD7: 27.616208 | CE7: 22.641923 | CF7: 23.81363 | CG7: 27.929923 | CH7: 23.170477 | CI7: 24.048215 | CJ7: 24.038507 | CK7: 24.621211 | CL7: 25.793426 | CM7: 25.878017 | CN7: 25.458612 | CO7: 25.278775 | CP7: 25.87806 | CQ7: 24.569835 | CR7: 24.66647 | CS7: 24.181342 | CT7: 25.283817 | CU7: 25.301983 | CV7: 24.088669 | CW7: 24.314226 | CX7: 23.623911 | CY7: 24.30796 | CZ7: 23.969646 | DA7: 23.969646 | DB7: 23.973386 | DC7: 25.708195 | DD7: 25.822029 | DE7: 23.071058 | DF7: 21.572107 | DG7: 21.524793 | DH7: 21.728218 | DI7: 24.569634 | DJ7: 23.75623 | DK7: 23.719682 | DL7: 22.784681 | DM7: 27.281825 | DN7: 25.946277 | DO7: 25.946325 | DP7: 25.409358 | DQ7: 25.458612 | DR7: 23.75549 | DS7: 25.841215 | DT7: 23.941391 | DU7: 23.859324 | DV7: 24.061617 | DW7: 22.718517 | DX7: 22.702886 | DY7: 23.308507 | DZ7: 23.47315 | EA7: 22.502107 | EB7: 22.37419 | EC7: 23.914704 | ED7: 23.79522 | EE7: 23.745438 | EF7: 24.931044 | EG7: 22.480422 | EH7: 25.511015 | EI7: 24.162009 | EJ7: 26.347604 | EK7: 24.088664 | EL7: 24.088664 | EM7: 23.416027 | EN7: 24.48954 | EO7: 24.746595 | EP7: 24.746595 | EQ7: 25.240097 | ER7: 25.239607 | ES7: 23.380539 | ET7: 23.380539 | EU7: 25.306135 | EV7: 24.30376 | EW7: 23.354493 | EX7: 24.463893 | EY7: 24.463893 | EZ7: 25.796184 | FA7: 22.900514 | FB7: 25.278775 | FC7: 27.929528 | FD7: 22.531479 | FE7: 27.929528 | FF7: 25.238453 | FG7: 24.187197 | FH7: 25.17527 | FI7: 22.140283 | FJ7: 24.179614 | FK7: 23.350487 | FL7: 25.681085 | FM7: 25.560264 | FN7: 25.507182 | FO7: 24.179633 | FP7: 24.179614 | FQ7: 24.179626 | FR7: 26.009556 | FS7: 26.009556 | FT7: 25.004319 | FU7: 25.025639 | FV7: 24.937311 | FW7: 25.569735 | FX7: 23.683322 | FY7: 26.325711 | FZ7: 26.302539 | GA7: 24.200493 | GB7: 25.837573 | GC7: 24.269626 | GD7: 24.107379 | GE7: 24.061087 | GF7: 23.280192 | GG7: 22.428472 | GH7: 21.605474 | GI7: 21.678571 | GJ7: 24.094029 | GK7: 25.804446
B8: 43431.104 | C8: 23.769285 | D8: 23.796137 | E8: 23.785387 | F8: 23.769261 | G8: 24.192649 | H8: 25.687246 | I8: 25.770905 | J8: 25.726236 | K8: 24.753126 | L8: 23.852307 | M8: 25.414743 | N8: 24.88779 | O8: 24.09493 | P8: 25.743283 | Q8: 24.094633 | R8: 23.378642 | S8: 23.407155 | T8: 23.8676 | U8: 24.109573 | V8: 23.896677 | W8: 23.796296 | X8: 26.314657 | Y8: 22.929631 | Z8: 24.709016 | AA8: 24.091344 | AB8: 22.393253 | AC8: 23.635351 | AD8: 23.791731 | AE8: 22.557671 | AF8: 25.871764 | AG8: 23.926474 | AH8: 23.18231 | AI8: 23.250139 | AJ8: 25.641078 | AK8: 22.561929 | AL8: 21.143593 | AM8: 24.783723 | AN8: 24.266679 | AO8: 24.937268 | AP8: 24.169331 | AQ8: 23.286052 | AR8: 24.439198 | AS8: 23.879136 | AT8: 24.076917 | AU8: 23.951971 | AV8: 23.936574 | AW8: 23.961291 | AX8: 23.920468 | AY8: 25.646925 | AZ8: 25.702168 | BA8: 25.646725 | BB8: 25.64679 | BC8: 22.166583 | BD8: 24.136611 | BE8: 24.131948 | BF8: 25.240408 | BG8: 22.573907 | BH8: 22.573907 | BI8: 24.228757 | BJ8: 23.030465 | BK8: 24.422989 | BL8: 24.639679 | BM8: 24.639679 | BN8: 24.723586 | BO8: 25.457672 | BP8: 23.756614 | BQ8: 24.47547 | BR8: 24.276627 | BS8: 24.213932 | BT8: 24.422989 | BU8: 23.936574 | BV8: 23.835411 | BW8: 23.876395 | BX8: 24.3343 | BY8: 24.335538 | BZ8: 23.753673 | CA8: 23.101139 | CB8: 23.896677 | CC8: 23.394474 | CD8: 27.702674 | CE8: 22.640723 | CF8: 23.81251 | CG8: 27.899536 | CH8: 23.180442 | CI8: 24.060495 | CJ8: 24.060519 | CK8: 24.59548 | CL8: 25.785051 | CM8: 25.872838 | CN8: 25.445312 | CO8: 25.265588 | CP8: 25.87288 | CQ8: 24.544517 | CR8: 24.639679 | CS8: 24.173597 | CT8: 25.259256 | CU8: 25.277413 | CV8: 24.076922 | CW8: 24.291701 | CX8: 23.606584 | CY8: 24.285907 | CZ8: 23.961291 | DA8: 23.961291 | DB8: 23.965293 | DC8: 25.693092 | DD8: 25.806044 | DE8: 23.019413 | DF8: 21.591253 | DG8: 21.541671 | DH8: 21.718555 | DI8: 24.56464 | DJ8: 23.816249 | DK8: 23.782321 | DL8: 22.751002 | DM8: 27.252143 | DN8: 25.942538 | DO8: 25.942587 | DP8: 25.396542 | DQ8: 25.445312 | DR8: 23.673651 | DS8: 25.712535 | DT8: 23.936574 | DU8: 23.854541 | DV8: 24.058951 | DW8: 22.736652 | DX8: 22.71376 | DY8: 23.306857 | DZ8: 23.546644 | EA8: 22.504633 | EB8: 22.376532 | EC8: 23.900793 | ED8: 23.78298 | EE8: 23.733896 | EF8: 24.920192 | EG8: 22.479274 | EH8: 25.394172 | EI8: 24.15352 | EJ8: 26.219909 | EK8: 24.076917 | EL8: 24.076917 | EM8: 23.412387 | EN8: 24.490921 | EO8: 24.723586 | EP8: 24.723586 | EQ8: 25.228663 | ER8: 25.228172 | ES8: 23.338453 | ET8: 23.338453 | EU8: 25.282416 | EV8: 24.243511 | EW8: 23.341439 | EX8: 24.422989 | EY8: 24.422989 | EZ8: 25.789372 | FA8: 22.921949 | FB8: 25.265588 | FC8: 27.899141 | FD8: 22.504748 | FE8: 27.899141 | FF8: 25.227017 | FG8: 24.173984 | FH8: 25.168012 | FI8: 22.145045 | FJ8: 24.173684 | FK8: 23.29808 | FL8: 25.659095 | FM8: 25.54475 | FN8: 25.491875 | FO8: 24.173703 | FP8: 24.173684 | FQ8: 24.173696 | FR8: 25.880285 | FS8: 25.880285 | FT8: 24.881821 | FU8: 24.902434 | FV8: 24.81457 | FW8: 25.438596 | FX8: 23.678798 | FY8: 26.308268 | FZ8: 26.286251 | GA8: 24.191838 | GB8: 25.828636 | GC8: 24.249659 | GD8: 24.105446 | GE8: 24.061038 | GF8: 23.269839 | GG8: 22.40758 | GH8: 21.612803 | GI8: 21.68552 | GJ8: 24.088957 | GK8: 25.675432
B9: 43431.125 | C9: 23.718204 | D9: 23.744562 | E9: 23.73401 | F9: 23.71818 | G9: 24.132232 | H9: 25.664804 | I9: 25.745702 | J9: 25.70267 | K9: 24.696433 | L9: 23.801273 | M9: 25.337793 | N9: 24.813078 | O9: 24.036238 | P9: 25.694612 | Q9: 24.022681 | R9: 23.337387 | S9: 23.365555 | T9: 23.808844 | U9: 24.042258 | V9: 23.775704 | W9: 23.702327 | X9: 26.234743 | Y9: 22.83192 | Z9: 24.677284 | AA9: 24.030968 | AB9: 22.340344 | AC9: 23.575896 | AD9: 23.732089 | AE9: 22.491228 | AF9: 25.817801 | AG9: 23.867973 | AH9: 23.015876 | AI9: 23.101707 | AJ9: 25.558371 | AK9: 22.499437 | AL9: 21.108935 | AM9: 24.696542 | AN9: 24.182663 | AO9: 24.831447 | AP9: 24.115056 | AQ9: 23.240651 | AR9: 24.374417 | AS9: 23.816239 | AT9: 24.017346 | AU9: 23.888872 | AV9: 23.870629 | AW9: 23.898165 | AX9: 23.857462 | AY9: 25.555764 | AZ9: 25.617693 | BA9: 25.555564 | BB9: 25.555629 | BC9: 22.115859 | BD9: 24.075799 | BE9: 24.071107 | BF9: 25.163143 | BG9: 22.50614 | BH9: 22.50614 | BI9: 24.139434 | BJ9: 22.9834 | BK9: 24.358644 | BL9: 24.645534 | BM9: 24.645534 | BN9: 24.654774 | BO9: 25.390299 | BP9: 23.69706 | BQ9: 24.465683 | BR9: 24.209575 | BS9: 24.144284 | BT9: 24.358644 | BU9: 23.870629 | BV9: 23.769917 | BW9: 23.834022 | BX9: 24.272348 | BY9: 24.273825 | BZ9: 23.703799 | CA9: 23.053158 | CB9: 23.775704 | CC9: 23.325859 | CD9: 27.595379 | CE9: 22.585033 | CF9: 23.7444 | CG9: 27.814809 | CH9: 23.09406 | CI9: 23.964043 | CJ9: 23.942198 | CK9: 24.586555 | CL9: 25.72928 | CM9: 25.81733 | CN9: 25.376098 | CO9: 25.191737 | CP9: 25.817372 | CQ9: 24.548385 | CR9: 24.645534 | CS9: 24.112499 | CT9: 25.187432 | CU9: 25.20554 | CV9: 24.017351 | CW9: 24.229837 | CX9: 23.553067 | CY9: 24.224232 | CZ9: 23.898165 | DA9: 23.898165 | DB9: 23.912008 | DC9: 25.624664 | DD9: 25.734827 | DE9: 22.939395 | DF9: 21.532307 | DG9: 21.485834 | DH9: 21.678188 | DI9: 24.481773 | DJ9: 23.661778 | DK9: 23.62243 | DL9: 22.682429 | DM9: 27.169382 | DN9: 25.858891 | DO9: 25.85894 | DP9: 25.324988 | DQ9: 25.376098 | DR9: 23.596032 | DS9: 25.618927 | DT9: 23.870629 | DU9: 23.788764 | DV9: 24.010083 | DW9: 22.67298 | DX9: 22.653447 | DY9: 23.238614 | DZ9: 23.455446 | EA9: 22.457742 | EB9: 22.328853 | EC9: 23.85324 | ED9: 23.733488 | EE9: 23.683594 | EF9: 24.868433 | EG9: 22.424065 | EH9: 25.299946 | EI9: 24.08989 | EJ9: 26.136781 | EK9: 24.017346 | EL9: 24.017346 | EM9: 23.346315 | EN9: 24.402412 | EO9: 24.654774 | EP9: 24.654774 | EQ9: 25.148095 | ER9: 25.14786 | ES9: 23.273124 | ET9: 23.273124 | EU9: 25.211606 | EV9: 24.173686 | EW9: 23.292203 | EX9: 24.358644 | EY9: 24.358644 | EZ9: 25.704474 | FA9: 22.82426 | FB9: 25.191737 | FC9: 27.814416 | FD9: 22.430102 | FE9: 27.814416 | FF9: 25.147308 | FG9: 24.111599 | FH9: 25.086133 | FI9: 22.092951 | FJ9: 24.113019 | FK9: 23.215507 | FL9: 25.577754 | FM9: 25.463746 | FN9: 25.411844 | FO9: 24.113038 | FP9: 24.113019 | FQ9: 24.113031 | FR9: 25.724815 | FS9: 25.724815 | FT9: 24.789663 | FU9: 24.810061 | FV9: 24.722754 | FW9: 25.346286 | FX9: 23.629624 | FY9: 26.223212 | FZ9: 26.205935 | GA9: 24.137407 | GB9: 25.804509 | GC9: 24.188726 | GD9: 24.06129 | GE9: 24.025127 | GF9: 23.226589 | GG9: 22.349531 | GH9: 21.554399 | GI9: 21.628204 | GJ9: 24.031701 | GK9: 25.582
B10: 43431.146 | C10: 23.72866 | D10: 23.755702 | E10: 23.744876 | F10: 23.728637 | G10: 24.131862 | H10: 25.716046 | I10: 25.796008 | J10: 25.753 | K10: 24.683197 | L10: 23.813438 | M10: 25.412534 | N10: 24.876037 | O10: 24.05267 | P10: 25.740262 | Q10: 24.179047 | R10: 23.342345 | S10: 23.370517 | T10: 23.824568 | U10: 24.045251 | V10: 23.771967 | W10: 23.700739 | X10: 26.310453 | Y10: 22.856357 | Z10: 24.661243 | AA10: 24.034885 | AB10: 22.335541 | AC10: 23.595709 | AD10: 23.75151 | AE10: 22.482898 | AF10: 25.859569 | AG10: 23.884409 | AH10: 23.044992 | AI10: 23.131209 | AJ10: 25.634111 | AK10: 22.492859 | AL10: 21.106712 | AM10: 24.764089 | AN10: 24.246585 | AO10: 24.918554 | AP10: 24.119432 | AQ10: 23.247527 | AR10: 24.399901 | AS10: 23.820306 | AT10: 24.018279 | AU10: 23.892917 | AV10: 23.878462 | AW10: 23.9022 | AX10: 23.86155 | AY10: 25.626678 | AZ10: 25.688768 | BA10: 25.626479 | BB10: 25.626544 | BC10: 22.072633 | BD10: 24.085766 | BE10: 24.081067 | BF10: 25.289024 | BG10: 22.497176 | BH10: 22.497176 | BI10: 24.31923 | BJ10: 22.993998 | BK10: 24.384234 | BL10: 24.624371 | BM10: 24.624371 | BN10: 24.691711 | BO10: 25.445786 | BP10: 23.716453 | BQ10: 24.44295 | BR10: 24.362571 | BS10: 24.297215 | BT10: 24.384234 | BU10: 23.878462 | BV10: 23.777311 | BW10: 23.855807 | BX10: 24.298508 | BY10: 24.300559 | BZ10: 23.707863 | CA10: 23.063563 | CB10: 23.771967 | CC10: 23.34027 | CD10: 27.586521 | CE10: 22.573935 | CF10: 23.753123 | CG10: 27.895079 | CH10: 23.113142 | CI10: 23.962198 | CJ10: 23.93632 | CK10: 24.572477 | CL10: 25.775353 | CM10: 25.859997 | CN10: 25.435429 | CO10: 25.253509 | CP10: 25.86004 | CQ10: 24.527388 | CR10: 24.624371 | CS10: 24.115412 | CT10: 25.248042 | CU10: 25.266144 | CV10: 24.018284 | CW10: 24.244684 | CX10: 23.565605 | CY10: 24.238593 | CZ10: 23.9022 | DA10: 23.9022 | DB10: 23.914208 | DC10: 25.682152 | DD10: 25.79235 | DE10: 23.110319 | DF10: 21.526338 | DG10: 21.479134 | DH10: 21.678585 | DI10: 24.522722 | DJ10: 23.654047 | DK10: 23.61437 | DL10: 22.727639 | DM10: 27.247789 | DN10: 25.928239 | DO10: 25.928287 | DP10: 25.385062 | DQ10: 25.435429 | DR10: 23.591653 | DS10: 25.671033 | DT10: 23.878462 | DU10: 23.796164 | DV10: 24.019545 | DW10: 22.666266 | DX10: 22.646595 | DY10: 23.235868 | DZ10: 23.447917 | EA10: 22.44398 | EB10: 22.321727 | EC10: 23.858275 | ED10: 23.738216 | EE10: 23.688194 | EF10: 24.879657 | EG10: 22.413256 | EH10: 25.35597 | EI10: 24.09103 | EJ10: 26.207157 | EK10: 24.018279 | EL10: 24.018279 | EM10: 23.343767 | EN10: 24.44482 | EO10: 24.691711 | EP10: 24.691711 | EQ10: 25.211312 | ER10: 25.210981 | ES10: 23.311911 | ET10: 23.311911 | EU10: 25.27109 | EV10: 24.324555 | EW10: 23.302747 | EX10: 24.384234 | EY10: 24.384234 | EZ10: 25.780502 | FA10: 22.848696 | FB10: 25.253509 | FC10: 27.894684 | FD10: 22.481471 | FE10: 27.894684 | FF10: 25.210203 | FG10: 24.112197 | FH10: 25.122568 | FI10: 22.086665 | FJ10: 24.116703 | FK10: 23.388123 | FL10: 25.649719 | FM10: 25.53968 | FN10: 25.486941 | FO10: 24.116722 | FP10: 24.116703 | FQ10: 24.116715 | FR10: 25.852883 | FS10: 25.852883 | FT10: 24.847959 | FU10: 24.868601 | FV10: 24.78117 | FW10: 25.396227 | FX10: 23.637658 | FY10: 26.316825 | FZ10: 26.295769 | GA10: 24.169925 | GB10: 25.853142 | GC10: 24.201045 | GD10: 24.065574 | GE10: 24.029573 | GF10: 23.227014 | GG10: 22.315817 | GH10: 21.551715 | GI10: 21.624899 | GJ10: 24.035351 | GK10: 25.633812
B11: 43431.167 | C11: 23.681579 | D11: 23.708405 | E11: 23.697665 | F11: 23.681555 | G11: 24.094248 | H11: 25.748127 | I11: 25.830276 | J11: 25.786868 | K11: 24.439113 | L11: 23.763608 | M11: 25.47685 | N11: 24.974046 | O11: 24.027587 | P11: 25.771315 | Q11: 24.188207 | R11: 23.307633 | S11: 23.334799 | T11: 23.797529 | U11: 24.020035 | V11: 23.764335 | W11: 23.682422 | X11: 26.311456 | Y11: 22.82172 | Z11: 24.414046 | AA11: 24.005572 | AB11: 22.301237 | AC11: 23.561935 | AD11: 23.719344 | AE11: 22.440874 | AF11: 25.882518 | AG11: 23.858115 | AH11: 23.026222 | AI11: 23.109556 | AJ11: 25.633235 | AK11: 22.459306 | AL11: 21.090256 | AM11: 24.785879 | AN11: 24.279927 | AO11: 24.929603 | AP11: 24.092468 | AQ11: 23.21526 | AR11: 24.361912 | AS11: 23.786313 | AT11: 23.978627 | AU11: 23.858816 | AV11: 23.849399 | AW11: 23.868043 | AX11: 23.827671 | AY11: 25.63667 | AZ11: 25.695083 | BA11: 25.63647 | BB11: 25.636535 | BC11: 22.05204 | BD11: 24.054188 | BE11: 24.04945 | BF11: 25.300494 | BG11: 22.450806 | BH11: 22.450806 | BI11: 24.311912 | BJ11: 22.968953 | BK11: 24.347161 | BL11: 24.367419 | BM11: 24.367419 | BN11: 24.636244 | BO11: 25.461829 | BP11: 23.684334 | BQ11: 24.277115 | BR11: 24.373853 | BS11: 24.307487 | BT11: 24.347161 | BU11: 23.849399 | BV11: 23.748825 | BW11: 23.831182 | BX11: 24.266458 | BY11: 24.268793 | BZ11: 23.6732 | CA11: 23.038013 | CB11: 23.764335 | CC11: 23.245668 | CD11: 27.496635 | CE11: 22.548702 | CF11: 23.72216 | CG11: 27.896142 | CH11: 23.07829 | CI11: 23.951511 | CJ11: 23.937217 | CK11: 24.357658 | CL11: 25.796395 | CM11: 25.882469 | CN11: 25.446733 | CO11: 25.255041 | CP11: 25.882511 | CQ11: 24.270324 | CR11: 24.367419 | CS11: 24.085734 | CT11: 25.32228 | CU11: 25.340365 | CV11: 23.978632 | CW11: 24.211342 | CX11: 23.538885 | CY11: 24.205421 | CZ11: 23.868043 | DA11: 23.868043 | DB11: 23.880854 | DC11: 25.699877 | DD11: 25.811603 | DE11: 23.111837 | DF11: 21.493626 | DG11: 21.447235 | DH11: 21.639413 | DI11: 24.47298 | DJ11: 23.652716 | DK11: 23.613975 | DL11: 22.833714 | DM11: 27.248828 | DN11: 25.951331 | DO11: 25.95138 | DP11: 25.393101 | DQ11: 25.446733 | DR11: 23.567771 | DS11: 25.569156 | DT11: 23.849399 | DU11: 23.767335 | DV11: 23.992903 | DW11: 22.63278 | DX11: 22.615138 | DY11: 23.207476 | DZ11: 23.371516 | EA11: 22.41968 | EB11: 22.291786 | EC11: 23.805195 | ED11: 23.695606 | EE11: 23.649949 | EF11: 24.852095 | EG11: 22.387917 | EH11: 25.263744 | EI11: 24.058238 | EJ11: 26.091764 | EK11: 23.978627 | EL11: 23.978627 | EM11: 23.314859 | EN11: 24.415306 | EO11: 24.636244 | EP11: 24.636244 | EQ11: 25.208364 | ER11: 25.207885 | ES11: 23.084322 | ET11: 23.084322 | EU11: 25.337643 | EV11: 24.33483 | EW11: 23.276323 | EX11: 24.347161 | EY11: 24.347161 | EZ11: 25.789449 | FA11: 22.814093 | FB11: 25.255041 | FC11: 27.895748 | FD11: 22.705388 | FE11: 27.895748 | FF11: 25.206759 | FG11: 24.077241 | FH11: 25.05189 | FI11: 22.056282 | FJ11: 24.088771 | FK11: 23.390163 | FL11: 25.652525 | FM11: 25.537018 | FN11: 25.485914 | FO11: 24.08879 | FP11: 24.088771 | FQ11: 24.088783 | FR11: 25.764914 | FS11: 25.764914 | FT11: 24.756641 | FU11: 24.777654 | FV11: 24.689751 | FW11: 25.290289 | FX11: 23.590363 | FY11: 26.32246 | FZ11: 26.296192 | GA11: 24.109287 | GB11: 25.889325 | GC11: 24.168858 | GD11: 24.039604 | GE11: 24.004757 | GF11: 23.185044 | GG11: 22.293346 | GH11: 21.518928 | GI11: 21.592563 | GJ11: 24.006329 | GK11: 25.531385
B12: 43431.188 | C12: 23.727387 | D12: 23.754719 | E12: 23.743777 | F12: 23.727363 | G12: 24.159026 | H12: 25.834511 | I12: 25.902387 | J12: 25.862344 | K12: 24.470939 | L12: 23.816474 | M12: 25.517792 | N12: 24.985831 | O12: 24.093567 | P12: 25.836318 | Q12: 24.280405 | R12: 23.321711 | S12: 23.351212 | T12: 23.860282 | U12: 24.080035 | V12: 23.818465 | W12: 23.736337 | X12: 26.413035 | Y12: 22.845717 | Z12: 24.452171 | AA12: 24.067938 | AB12: 22.339287 | AC12: 23.635148 | AD12: 23.791427 | AE12: 22.50135 | AF12: 25.940383 | AG12: 23.921572 | AH12: 23.051565 | AI12: 23.137236 | AJ12: 25.706765 | AK12: 22.505651 | AL12: 21.098451 | AM12: 24.863006 | AN12: 24.354384 | AO12: 25.008705 | AP12: 24.153086 | AQ12: 23.283872 | AR12: 24.442899 | AS12: 23.849114 | AT12: 24.042213 | AU12: 23.921766 | AV12: 23.911057 | AW12: 23.931033 | AX12: 23.890467 | AY12: 25.717231 | AZ12: 25.774232 | BA12: 25.717031 | BB12: 25.717096 | BC12: 22.096837 | BD12: 24.119589 | BE12: 24.114967 | BF12: 25.400483 | BG12: 22.517664 | BH12: 22.517664 | BI12: 24.380522 | BJ12: 23.013777 | BK12: 24.42724 | BL12: 24.411956 | BM12: 24.411956 | BN12: 24.699601 | BO12: 25.516723 | BP12: 23.756311 | BQ12: 24.329901 | BR12: 24.470822 | BS12: 24.402094 | BT12: 24.42724 | BU12: 23.911057 | BV12: 23.810849 | BW12: 23.929051 | BX12: 24.341561 | BY12: 24.343742 | BZ12: 23.735294 | CA12: 23.084309 | CB12: 23.818465 | CC12: 23.273904 | CD12: 27.546954 | CE12: 22.584053 | CF12: 23.776959 | CG12: 28.003839 | CH12: 23.115571 | CI12: 24.009607 | CJ12: 23.993832 | CK12: 24.405523 | CL12: 25.855697 | CM12: 25.940457 | CN12: 25.507759 | CO12: 25.316954 | CP12: 25.9405 | CQ12: 24.31285 | CR12: 24.411956 | CS12: 24.148038 | CT12: 25.351243 | CU12: 25.369373 | CV12: 24.042218 | CW12: 24.282035 | CX12: 23.593668 | CY12: 24.275877 | CZ12: 23.931033 | DA12: 23.931033 | DB12: 23.943304 | DC12: 25.758487 | DD12: 25.867481 | DE12: 23.191347 | DF12: 21.538137 | DG12: 21.49165 | DH12: 21.670636 | DI12: 24.532228 | DJ12: 23.705406 | DK12: 23.665586 | DL12: 22.854668 | DM12: 27.354026 | DN12: 26.014642 | DO12: 26.014691 | DP12: 25.454457 | DQ12: 25.507759 | DR12: 23.701019 | DS12: 25.725479 | DT12: 23.911057 | DU12: 23.828745 | DV12: 24.05345 | DW12: 22.679289 | DX12: 22.657511 | DY12: 23.252471 | DZ12: 23.414286 | EA12: 22.449191 | EB12: 22.323085 | EC12: 23.862003 | ED12: 23.752488 | EE12: 23.706863 | EF12: 24.902037 | EG12: 22.422815 | EH12: 25.396739 | EI12: 24.124781 | EJ12: 26.21951 | EK12: 24.042213 | EL12: 24.042213 | EM12: 23.35992 | EN12: 24.471998 | EO12: 24.699601 | EP12: 24.699601 | EQ12: 25.270247 | ER12: 25.269805 | ES12: 23.430743 | ET12: 23.430743 | EU12: 25.369697 | EV12: 24.42944 | EW12: 23.322996 | EX12: 24.42724 | EY12: 24.42724 | EZ12: 25.866352 | FA12: 22.838135 | FB12: 25.316954 | FC12: 28.003443 | FD12: 22.606861 | FE12: 28.003443 | FF12: 25.268765 | FG12: 24.140647 | FH12: 25.149518 | FI12: 22.093291 | FJ12: 24.150709 | FK12: 23.46643 | FL12: 25.73083 | FM12: 25.60896 | FN12: 25.555795 | FO12: 24.150728 | FP12: 24.150709 | FQ12: 24.150721 | FR12: 25.800898 | FS12: 25.800898 | FT12: 24.886439 | FU12: 24.907304 | FV12: 24.819277 | FW12: 25.43879 | FX12: 23.634635 | FY12: 26.407649 | FZ12: 26.381018 | GA12: 24.178799 | GB12: 25.951318 | GC12: 24.238385 | GD12: 24.097926 | GE12: 24.060851 | GF12: 23.218497 | GG12: 22.339392 | GH12: 21.565992 | GI12: 21.637975 | GJ12: 24.068168 | GK12: 25.686646
B13: 43431.208 | C13: 23.797262 | D13: 23.825478 | E13: 23.814182 | F13: 23.797238 | G13: 24.21251 | H13: 25.834426 | I13: 25.90777 | J13: 25.864376 | K13: 24.789377 | L13: 23.889145 | M13: 25.491419 | N13: 24.967573 | O13: 24.161589 | P13: 25.840131 | Q13: 24.304851 | R13: 23.385905 | S13: 23.414526 | T13: 23.918643 | U13: 24.108833 | V13: 23.859015 | W13: 23.777418 | X13: 26.390356 | Y13: 22.917243 | Z13: 24.776927 | AA13: 24.099111 | AB13: 22.386856 | AC13: 23.696312 | AD13: 23.854466 | AE13: 22.528793 | AF13: 25.958986 | AG13: 23.979271 | AH13: 23.08573 | AI13: 23.177857 | AJ13: 25.718106 | AK13: 22.538445 | AL13: 21.131356 | AM13: 24.902292 | AN13: 24.399974 | AO13: 25.068905 | AP13: 24.174264 | AQ13: 23.312998 | AR13: 24.522767 | AS13: 23.895873 | AT13: 24.097799 | AU13: 23.968632 | AV13: 23.949134 | AW13: 23.977893 | AX13: 23.937366 | AY13: 25.750832 | AZ13: 25.795171 | BA13: 25.750631 | BB13: 25.750696 | BC13: 22.154474 | BD13: 24.166441 | BE13: 24.161784 | BF13: 25.398877 | BG13: 22.541401 | BH13: 22.541401 | BI13: 24.400034 | BJ13: 23.04992 | BK13: 24.506434 | BL13: 24.750668 | BM13: 24.750668 | BN13: 24.799427 | BO13: 25.533274 | BP13: 23.819257 | BQ13: 24.56133 | BR13: 24.494962 | BS13: 24.425115 | BT13: 24.506434 | BU13: 23.949134 | BV13: 23.848108 | BW13: 24.013948 | BX13: 24.417044 | BY13: 24.41953 | BZ13: 23.770403 | CA13: 23.121294 | CB13: 23.859015 | CC13: 23.419324 | CD13: 27.502434 | CE13: 22.634746 | CF13: 23.818997 | CG13: 27.979794 | CH13: 23.181646 | CI13: 24.026712 | CJ13: 23.999734 | CK13: 24.702818 | CL13: 25.872946 | CM13: 25.959205 | CN13: 25.524093 | CO13: 25.33755 | CP13: 25.959247 | CQ13: 24.651264 | CR13: 24.750668 | CS13: 24.184029 | CT13: 25.34577 | CU13: 25.364894 | CV13: 24.097804 | CW13: 24.338541 | CX13: 23.646215 | CY13: 24.331805 | CZ13: 23.977893 | DA13: 23.977893 | DB13: 23.97524 | DC13: 25.786362 | DD13: 25.903212 | DE13: 23.205116 | DF13: 21.571214 | DG13: 21.52466 | DH13: 21.720325 | DI13: 24.600301 | DJ13: 23.752531 | DK13: 23.720761 | DL13: 22.811152 | DM13: 27.330539 | DN13: 26.027238 | DO13: 26.027287 | DP13: 25.472207 | DQ13: 25.524093 | DR13: 23.757377 | DS13: 25.912014 | DT13: 23.949134 | DU13: 23.866483 | DV13: 24.066135 | DW13: 22.711767 | DX13: 22.695557 | DY13: 23.305035 | DZ13: 23.376445 | EA13: 22.48202 | EB13: 22.365188 | EC13: 23.91002 | ED13: 23.795843 | EE13: 23.748274 | EF13: 24.941934 | EG13: 22.473672 | EH13: 25.565702 | EI13: 24.164851 | EJ13: 26.392964 | EK13: 24.097799 | EL13: 24.097799 | EM13: 23.414886 | EN13: 24.51715 | EO13: 24.799427 | EP13: 24.799427 | EQ13: 25.294766 | ER13: 25.294275 | ES13: 23.396397 | ET13: 23.396397 | EU13: 25.365849 | EV13: 24.451087 | EW13: 23.368365 | EX13: 24.506434 | EY13: 24.506434 | EZ13: 25.8758 | FA13: 22.909611 | FB13: 25.33755 | FC13: 27.979399 | FD13: 22.563094 | FE13: 27.979399 | FF13: 25.293121 | FG13: 24.191804 | FH13: 25.213855 | FI13: 22.134547 | FJ13: 24.18167 | FK13: 23.480925 | FL13: 25.744577 | FM13: 25.620516 | FN13: 25.56663 | FO13: 24.18169 | FP13: 24.18167 | FQ13: 24.181683 | FR13: 26.079813 | FS13: 26.079813 | FT13: 25.056214 | FU13: 25.077401 | FV13: 24.988968 | FW13: 25.616902 | FX13: 23.701395 | FY13: 26.374962 | FZ13: 26.342985 | GA13: 24.26599 | GB13: 25.957281 | GC13: 24.292049 | GD13: 24.107674 | GE13: 24.061094 | GF13: 23.271735 | GG13: 22.397131 | GH13: 21.599984 | GI13: 21.673093 | GJ13: 24.09574 | GK13: 25.872039
B14: 43431.229 | C14: 23.826964 | D14: 23.856836 | E14: 23.844878 | F14: 23.82694 | G14: 24.184556 | H14: 25.625788 | I14: 25.708104 | J14: 25.661449 | K14: 24.47037 | L14: 23.917425 | M14: 25.21441 | N14: 24.714998 | O14: 24.233621 | P14: 25.658755 | Q14: 24.083057 | R14: 23.400298 | S14: 23.429115 | T14: 23.988087 | U14: 24.088314 | V14: 23.858507 | W14: 23.756649 | X14: 26.100253 | Y14: 22.799439 | Z14: 24.448733 | AA14: 24.085599 | AB14: 22.358288 | AC14: 23.788139 | AD14: 23.944223 | AE14: 22.494919 | AF14: 25.75832 | AG14: 24.050011 | AH14: 22.98516 | AI14: 23.070822 | AJ14: 25.494459 | AK14: 22.497566 | AL14: 21.099328 | AM14: 24.668329 | AN14: 24.167443 | AO14: 24.811311 | AP14: 24.165588 | AQ14: 23.323641 | AR14: 24.635876 | AS14: 23.860226 | AT14: 24.062163 | AU14: 23.932853 | AV14: 23.909615 | AW14: 23.942069 | AX14: 23.901762 | AY14: 25.514713 | AZ14: 25.560645 | BA14: 25.514513 | BB14: 25.514578 | BC14: 22.118193 | BD14: 24.199761 | BE14: 24.191332 | BF14: 25.12748 | BG14: 22.511938 | BH14: 22.511938 | BI14: 24.214907 | BJ14: 23.074958 | BK14: 24.617544 | BL14: 24.405575 | BM14: 24.405575 | BN14: 24.892568 | BO14: 25.348055 | BP14: 23.908881 | BQ14: 24.322431 | BR14: 24.264277 | BS14: 24.195774 | BT14: 24.617544 | BU14: 23.909615 | BV14: 23.809274 | BW14: 24.150401 | BX14: 24.517174 | BY14: 24.521439 | BZ14: 23.77586 | CA14: 23.148203 | CB14: 23.858507 | CC14: 23.238201 | CD14: 27.416401 | CE14: 22.642568 | CF14: 23.781245 | CG14: 27.672219 | CH14: 23.089567 | CI14: 23.958524 | CJ14: 23.926063 | CK14: 24.387172 | CL14: 25.670572 | CM14: 25.757619 | CN14: 25.329022 | CO14: 25.14442 | CP14: 25.757662 | CQ14: 24.305356 | CR14: 24.405575 | CS14: 24.16633 | CT14: 25.107633 | CU14: 25.124768 | CV14: 24.062168 | CW14: 24.392139 | CX14: 23.707941 | CY14: 24.384123 | CZ14: 23.942069 | DA14: 23.942069 | DB14: 23.973792 | DC14: 25.59983 | DD14: 25.721844 | DE14: 23.024115 | DF14: 21.531012 | DG14: 21.483798 | DH14: 21.727261 | DI14: 24.446827 | DJ14: 23.767901 | DK14: 23.737303 | DL14: 22.567461 | DM14: 27.030101 | DN14: 25.786251 | DO14: 25.7863 | DP14: 25.278078 | DQ14: 25.329022 | DR14: 23.783469 | DS14: 26.252895 | DT14: 23.909615 | DU14: 23.827554 | DV14: 24.066918 | DW14: 22.669963 | DX14: 22.658085 | DY14: 23.249488 | DZ14: 23.303319 | EA14: 22.460308 | EB14: 22.340789 | EC14: 23.92799 | ED14: 23.808463 | EE14: 23.758663 | EF14: 24.970962 | EG14: 22.479345 | EH14: 25.86008 | EI14: 24.146795 | EJ14: 26.708852 | EK14: 24.062163 | EL14: 24.062163 | EM14: 23.358323 | EN14: 24.374856 | EO14: 24.892568 | EP14: 24.892568 | EQ14: 25.114056 | ER14: 25.113576 | ES14: 23.14337 | ET14: 23.14337 | EU14: 25.138844 | EV14: 24.218308 | EW14: 23.421136 | EX14: 24.617544 | EY14: 24.617544 | EZ14: 25.637902 | FA14: 22.791819 | FB14: 25.14442 | FC14: 27.671828 | FD14: 22.322439 | FE14: 27.671828 | FF14: 25.112447 | FG14: 24.166651 | FH14: 25.06221 | FI14: 22.107278 | FJ14: 24.166434 | FK14: 23.294756 | FL14: 25.510243 | FM14: 25.39797 | FN14: 25.34304 | FO14: 24.166453 | FP14: 24.166434 | FQ14: 24.166446 | FR14: 26.54385 | FS14: 26.54385 | FT14: 25.354199 | FU14: 25.375366 | FV14: 25.287362 | FW14: 25.934723 | FX14: 23.723374 | FY14: 26.068712 | FZ14: 26.043843 | GA14: 24.320505 | GB14: 25.764396 | GC14: 24.3408 | GD14: 24.104083 | GE14: 24.061004 | GF14: 23.279167 | GG14: 22.358867 | GH14: 21.580617 | GI14: 21.652362 | GJ14: 24.084845 | GK14: 26.209792
B15: 43431.25 | C15: 23.812149 | D15: 23.842484 | E15: 23.830341 | F15: 23.812126 | G15: 24.214928 | H15: 25.675498 | I15: 25.756437 | J15: 25.710108 | K15: 24.774768 | L15: 23.89983 | M15: 25.265556 | N15: 24.737433 | O15: 24.249734 | P15: 25.706626 | Q15: 24.191267 | R15: 23.317609 | S15: 23.349366 | T15: 24.000447 | U15: 24.10173 | V15: 23.871309 | W15: 23.777296 | X15: 26.168533 | Y15: 22.883154 | Z15: 24.734507 | AA15: 24.093031 | AB15: 22.357184 | AC15: 23.81472 | AD15: 23.971614 | AE15: 22.492706 | AF15: 25.800322 | AG15: 24.061887 | AH15: 23.063807 | AI15: 23.148565 | AJ15: 25.555199 | AK15: 22.496096 | AL15: 21.081026 | AM15: 24.735919 | AN15: 24.209852 | AO15: 24.834961 | AP15: 24.173163 | AQ15: 23.312126 | AR15: 24.698238 | AS15: 23.886961 | AT15: 24.094645 | AU15: 23.959582 | AV15: 23.932062 | AW15: 23.968858 | AX15: 23.928244 | AY15: 25.605886 | AZ15: 25.643229 | BA15: 25.605686 | BB15: 25.605751 | BC15: 22.160799 | BD15: 24.209627 | BE15: 24.203788 | BF15: 25.231637 | BG15: 22.511085 | BH15: 22.511085 | BI15: 24.279675 | BJ15: 23.055017 | BK15: 24.676933 | BL15: 24.676871 | BM15: 24.676871 | BN15: 24.895128 | BO15: 25.383173 | BP15: 23.936232 | BQ15: 24.491844 | BR15: 24.394096 | BS15: 24.314247 | BT15: 24.676933 | BU15: 23.932062 | BV15: 23.831118 | BW15: 24.198238 | BX15: 24.560235 | BY15: 24.564445 | BZ15: 23.766619 | CA15: 23.130839 | CB15: 23.871309 | CC15: 23.374857 | CD15: 27.311239 | CE15: 22.618452 | CF15: 23.723459 | CG15: 27.744611 | CH15: 23.132002 | CI15: 23.972061 | CJ15: 23.939129 | CK15: 24.625056 | CL15: 25.712146 | CM15: 25.799573 | CN15: 25.370983 | CO15: 25.196113 | CP15: 25.799615 | CQ15: 24.578115 | CR15: 24.676871 | CS15: 24.185818 | CT15: 25.142493 | CU15: 25.161627 | CV15: 24.09465 | CW15: 24.419892 | CX15: 23.710772 | CY15: 24.4108 | CZ15: 23.968858 | DA15: 23.968858 | DB15: 23.966815 | DC15: 25.641261 | DD15: 25.763073 | DE15: 23.094979 | DF15: 21.532505 | DG15: 21.485293 | DH15: 21.709573 | DI15: 24.507925 | DJ15: 23.782518 | DK15: 23.751956 | DL15: 22.571177 | DM15: 27.100813 | DN15: 25.820269 | DO15: 25.820317 | DP15: 25.31982 | DQ15: 25.370983 | DR15: 23.838016 | DS15: 26.548625 | DT15: 23.932062 | DU15: 23.849772 | DV15: 24.062803 | DW15: 22.668573 | DX15: 22.659917 | DY15: 23.287441 | DZ15: 23.213933 | EA15: 22.439841 | EB15: 22.328894 | EC15: 23.898888 | ED15: 23.792828 | EE15: 23.748643 | EF15: 24.952231 | EG15: 22.454902 | EH15: 26.102934 | EI15: 24.164391 | EJ15: 26.961905 | EK15: 24.094645 | EL15: 24.094645 | EM15: 23.396845 | EN15: 24.430998 | EO15: 24.895128 | EP15: 24.895128 | EQ15: 25.164854 | ER15: 25.164499 | ES15: 23.172653 | ET15: 23.172653 | EU15: 25.168211 | EV15: 24.336093 | EW15: 23.420742 | EX15: 24.676933 | EY15: 24.676933 | EZ15: 25.666121 | FA15: 22.875465 | FB15: 25.196113 | FC15: 27.744219 | FD15: 22.32066 | FE15: 27.744219 | FF15: 25.163664 | FG15: 24.199875 | FH15: 25.112587 | FI15: 22.106734 | FJ15: 24.181363 | FK15: 23.366152 | FL15: 25.582068 | FM15: 25.468729 | FN15: 25.415843 | FO15: 24.181383 | FP15: 24.181363 | FQ15: 24.181376 | FR15: 26.679782 | FS15: 26.679782 | FT15: 25.60529 | FU15: 25.628592 | FV15: 25.538212 | FW15: 26.214123 | FX15: 23.705455 | FY15: 26.140657 | FZ15: 26.116673 | GA15: 24.302333 | GB15: 25.810796 | GC15: 24.363593 | GD15: 24.106279 | GE15: 24.061059 | GF15: 23.260215 | GG15: 22.403546 | GH15: 21.592666 | GI15: 21.662437 | GJ15: 24.089904 | GK15: 26.503308
... B51: 43431.999 | C51: 25.485623 | D51: 25.521726 | E51: 25.507275 | F51: 25.485597 | G51: 25.667702 | H51: 27.396847 | I51: 27.498266 | J51: 27.444525 | K51: 26.178647 | L51: 25.599707 | M51: 27.124338 | N51: 26.590279 | O51: 26.042845 | P51: 27.445834 | Q51: 25.91858 | R51: 24.810871 | S51: 24.848649 | T51: 25.727264 | U51: 25.590787 | V51: 25.352491 | W51: 25.270142 | X51: 27.920906 | Y51: 24.517848 | Z51: 26.160174 | AA51: 25.591494 | AB51: 23.765243 | AC51: 25.540526 | AD51: 25.705806 | AE51: 23.865346 | AF51: 27.566817 | AG51: 25.79118 | AH51: 24.809621 | AI51: 24.863687 | AJ51: 27.251184 | AK51: 24.009822 | AL51: 22.398951 | AM51: 26.218431 | AN51: 25.622047 | AO51: 26.314023 | AP51: 25.66825 | AQ51: 24.920343 | AR51: 26.436148 | AS51: 25.249679 | AT51: 25.497773 | AU51: 25.326878 | AV51: 25.371711 | AW51: 25.344891 | AX51: 25.259712 | AY51: 27.178451 | AZ51: 27.193341 | BA51: 27.178238 | BB51: 27.178307 | BC51: 23.632306 | BD51: 25.837092 | BE51: 25.807083 | BF51: 27.041891 | BG51: 23.856297 | BH51: 23.856297 | BI51: 25.981645 | BJ51: 24.513492 | BK51: 26.406921 | BL51: 26.092992 | BM51: 26.092992 | BN51: 26.781367 | BO51: 27.107666 | BP51: 26.153318 | BQ51: 25.934463 | BR51: 26.142209 | BS51: 26.056612 | BT51: 26.406921 | BU51: 25.371711 | BV51: 25.26503 | BW51: 25.883937 | BX51: 26.24653 | BY51: 26.251971 | BZ51: 25.349226 | CA51: 24.596582 | CB51: 25.352491 | CC51: 24.974825 | CD51: 27.198908 | CE51: 24.152119 | CF51: 25.242733 | CG51: 29.647954 | CH51: 24.732864 | CI51: 25.420337 | CJ51: 25.388191 | CK51: 26.071671 | CL51: 27.477142 | CM51: 27.566437 | CN51: 27.094559 | CO51: 26.890359 | CP51: 27.566482 | CQ51: 25.994013 | CR51: 26.092992 | CS51: 25.674449 | CT51: 26.974452 | CU51: 26.996212 | CV51: 25.497778 | CW51: 26.058899 | CX51: 25.425469 | CY51: 26.046508 | CZ51: 25.344891 | DA51: 25.344891 | DB51: 25.519969 | DC51: 27.393029 | DD51: 27.529042 | DE51: 24.731869 | DF51: 23.998977 | DG51: 23.955886 | DH51: 23.225419 | DI51: 26.061307 | DJ51: 25.266191 | DK51: 25.241095 | DL51: 24.436401 | DM51: 29.864424 | DN51: 27.528164 | DO51: 27.528216 | DP51: 27.03708 | DQ51: 27.094559 | DR51: 25.325603 | DS51: 28.505575 | DT51: 25.371711 | DU51: 25.284304 | DV51: 25.592693 | DW51: 24.113676 | DX51: 24.111364 | DY51: 24.803672 | DZ51: 24.999226 | EA51: 23.895698 | EB51: 23.761389 | EC51: 25.502034 | ED51: 25.389545 | EE51: 25.342682 | EF51: 26.47399 | EG51: 23.973919 | EH51: 28.051455 | EI51: 25.631517 | EJ51: 28.783171 | EK51: 25.378528 | EL51: 25.378528 | EM51: 24.915087 | EN51: 25.999124 | EO51: 26.781367 | EP51: 26.781367 | EQ51: 26.844252 | ER51: 26.844089 | ES51: 25.160862 | ET51: 25.160862 | EU51: 26.991122 | EV51: 26.083471 | EW51: 25.140683 | EX51: 26.406921 | EY51: 26.406921 | EZ51: 27.403475 | FA51: 24.509679 | FB51: 26.890359 | FC51: 29.605765 | FD51: 24.132192 | FE51: 29.605765 | FF51: 26.843707 | FG51: 25.667818 | FH51: 26.715147 | FI51: 23.48043 | FJ51: 25.676919 | FK51: 25.02301 | FL51: 27.110275 | FM51: 27.155103 | FN51: 27.114051 | FO51: 25.67694 | FP51: 25.676919 | FQ51: 25.676932 | FR51: 28.617417 | FS51: 28.617417 | FT51: 27.52886 | FU51: 27.554818 | FV51: 27.457622 | FW51: 28.184465 | FX51: 25.361003 | FY51: 28.022934 | FZ51: 28.00225 | GA51: 26.1291 | GB51: 27.566531 | GC51: 25.993314 | GD51: 25.594913 | GE51: 25.540574 | GF51: 24.823931 | GG51: 23.889055 | GH51: 22.796465 | GI51: 22.885171 | GJ51: 25.589266 | GK51: 28.462076
B53: Nota:

Sheet Cmg_Ener
B3: S/./MWh | C3: AGUAYTIA 13.8 | D3: AGUAYTIA 138 | E3: AGUAYTIA 22.9 | F3: AGUAYTIA 220 | G3: ALTO PRADERAS 220kV | H3: ARICOTA1 66 | I3: ARICOTA2 138 | J3: ARICOTA66 | K3: ASIA 220 | L3: AUCAYACU 138 | M3: AYAVIRI 138 | N3: AZANGARO 138 | O3: BELAUNDE 138 | P3: BOTIFLACA 138 | Q3: CACHIMAYO 138 | R3: CAHUA 10 | S3: CAHUA138 | T3: CAJAMARCA 220 | U3: CAJAMARQUILLA 220 | V3: CALLAHUANCA 60 | W3: CALLAHUANCA EDEGEL 220 | X3: CALLALLI 138 | Y3: CAMPO ARMIÑO 220 | Z3: CANTERA 220 | AA3: CARABAYLLO 220 | AB3: CARHUAMAYO 138 | AC3: CARHUAQUE10 | AD3: CARHUAQUERO 220 | AE3: CARIPA138 | AF3: CATKATO4.16 | AG3: CCORONA220 | AH3: CERRO DEL AGUILA 13.8 | AI3: CERRO DEL AGUILA 220 | AJ3: CERRO VERDE 138 | AK3: CH OROYA 50 | AL3: CHAGLLA 220 | AM3: CHARCANI I 33 | AN3: CHARCANI IV 33 | AO3: CHARCANI VI 33 | AP3: CHAVARRIA 220 | AQ3: CHEVES 220 | AR3: CHICLAYO 220 | AS3: CHILCA DOS 13.8 | AT3: CHILCA REP 220 | AU3: CHILCA UNO 220 | AV3: CHILCA500 | AW3: CHILCACTM220 | AX3: CHILCAI16 | AY3: CHILID10.5 | AZ3: CHILINA 138 | BA3: CHILINA 33 | BB3: CHILITG13.8 | BC3: CHIMAY220 | BD3: CHIMBOTE1 138 | BE3: CHIMBOTE1 220 | BF3: COMBAPATA 138 | BG3: CONDORCOCHA 138 | BH3: CONDORCOCHA 44 | BI3: COTARUSE 220 | BJ3: CPATO13.8 | BK3: CT ETEN 220 | BL3: CT INDEPENDENCIA 60 | BM3: CT PISCO 60 | BN3: CT PLANTA PUCALLPA 60 | BO3: CTILO217 | BP3: CUTERVO 138 | BQ3: DESIERTO 220 | BR3: DOLORESPATA 10.5 | BS3: DOLORESPATA 138 | BT3: ETEN 18 | BU3: FENIX 500 | BV3: FENIX18 | BW3: GALLITO CIEGO 60 | BX3: GUADALUPE 220 | BY3: GUADALUPE 60 | BZ3: HUACHO 220 | CA3: HUALLANCA 138 | CB3: HUAMPANI 60 | CC3: HUANCAVELICA 220 | CD3: HUANCHOR50 | CE3: HUANUCO 138 | CF3: HUANZA 220 | CG3: HUAYLLACHO 15 | CH3: HUAYUCACHI 220 | CI3: HUINCO 220 | CJ3: HUINCO12.5 | CK3: ICA 220 | CL3: ILO ELP 138 | CM3: ILO1 138 | CN3: ILO2 220 | CO3: ILO4-18 | CP3: ILOTG1 | CQ3: INDEPENDENCIA 220 | CR3: INDEPENDENCIA 60 | CS3: INDUSTRIALES 220 | CT3: JULIACA 138 | CU3: JULIACA10 | CV3: KALLPA16.5 | CW3: LA NIÑA 220 | CX3: LA RAMADA 220 | CY3: LANIÑA500 | CZ3: LAS FLORES 220 | DA3: LFLORES16.5 | DB3: LOMERA 220 | DC3: LOS HEROES 220 | DD3: LOS HEROES 66 | DE3: MACHUPICCHU 138 | DF3: MALPASO 50 | DG3: MALPASO6.9 | DH3: MARAÑON 60 | DI3: MARCONA 220 | DJ3: MATUCANA 220 | DK3: MATUCANA 12.5 | DL3: MAZUCO138 | DM3: MISAPUQUIO 33 | DN3: MOLLENDO 138 | DO3: MOLLENDO13.8 | DP3: MONTALVO220 | DQ3: MOQUEGUA 138 | DR3: MOYOPAMPA 60 | DS3: NCTUMBES60 | DT3: OLLEROS 500 | DU3: OLLEROS16.5 | DV3: OQUENDO60 | DW3: OROYA NUEVA 50 | DX3: OROYA220 | DY3: PACHACHACA 220 | DZ3: PACHACHACA50 | EA3: PARAGSHA2 138 | EB3: PARAGSHA2 220 | EC3: PARAMONGA EXISTENTE 138 | ED3: PARAMONGA NUEVA 138 | EE3: PARAMONGA NUEVA 220 | EF3: PARIAC 66 | EG3: PIEDRA BLANCA 34.5 kV | EH3: PIURA OESTE 220 | EI3: PLANICIE220 | EJ3: PLANTAETANOL 60 | EK3: PLATANAL13.8 | EL3: PLATANAL220 | EM3: POMACOCHA 220 | EN3: POROMA 220 | EO3: PUCALLPA 0.5 | EP3: PUCALLPA 60 | EQ3: PUERTO BRAVO 18 | ER3: PUERTO BRAVO 500 | ES3: PUERTO MALDONADO 0.5 | ET3: PUERTO MALDONADO 10 | EU3: PUNO 138 | EV3: QUENCORO 138 | EW3: QUITARACSA 220 | EX3: RECKA 220 | EY3: RECKA18 | EZ3: REPARTICIÓN 138 | FA3: RESTITUCIÓN 220 | FB3: S.E. ILO4 500 | FC3: SAN ANTONIO 15 | FD3: SAN GABAN 138 | FE3: SAN IGNACIO 15 | FF3: SAN JOSÉ 500 kV | FG3: SAN JUAN 220 | FH3: SAN NICOLAS 13.8 | FI3: SANTA ISABEL 220 | FJ3: SANTA ROSA 220 | FK3: SANTA TERESA 220 | FL3: SANTUARIO 138 | FM3: SOCABAYA 138 | FN3: SOCABAYA 220 | FO3: SROSATG7 | FP3: SROSATG8 | FQ3: SROSAUTI | FR3: TABLAZO 13.8 | FS3: TABLAZO 60 | FT3: TALARA 220 | FU3: TALARA13.2 | FV3: TALARA13.8 | FW3: TG5_16.5 | FX3: TINGO MARIA 138 | FY3: TINTAYA EXISTENTE 138 | FZ3: TINTAYA NUEVA 220 | GA3: TOCACHE 138 | GB3: TOQUEPALA 138 | GC3: TRUJILLO 220 | GD3: VENTANILLA 220 | GE3: VENTANILLA16 | GF3: VIZCARRA 220 | GG3: YANANGO220 | GH3: YAUPI13.8 | GI3: YAUPI138 | GJ3: ZAPALLAL 220 | GK3: ZORRITOS 220
B4: 43431.021 | C4: 23.861898 | D4: 23.89229 | E4: 23.880124 | F4: 23.861874 | G4: 24.246491 | H4: 25.796297 | I4: 25.89315 | J4: 25.844628 | K4: 24.554994 | L4: 23.950037 | M4: 25.589656 | N4: 25.062045 | O4: 24.213224 | P4: 25.864525 | Q4: 24.332817 | R4: 23.387597 | S4: 23.418455 | T4: 23.95427 | U4: 24.138377 | V4: 23.865533 | W4: 23.794142 | X4: 26.465406 | Y4: 22.904412 | Z4: 24.523938 | AA4: 24.134263 | AB4: 22.41349 | AC4: 23.756692 | AD4: 23.91471 | AE4: 22.542232 | AF4: 25.992736 | AG4: 24.012194 | AH4: 23.140634 | AI4: 23.218515 | AJ4: 25.754283 | AK4: 22.562555 | AL4: 21.119863 | AM4: 24.825033 | AN4: 24.223851 | AO4: 24.954694 | AP4: 24.214909 | AQ4: 23.328671 | AR4: 24.617597 | AS4: 23.914961 | AT4: 24.113659 | AU4: 23.987799 | AV4: 23.972983 | AW4: 23.997654 | AX4: 23.954079 | AY4: 25.768734 | AZ4: 25.82927 | BA4: 25.768533 | BB4: 25.768598 | BC4: 22.153706 | BD4: 24.216187 | BE4: 24.210457 | BF4: 25.46027 | BG4: 22.546694 | BH4: 22.546694 | BI4: 24.412386 | BJ4: 23.048716 | BK4: 24.596684 | BL4: 24.464125 | BM4: 24.464125 | BN4: 24.946697 | BO4: 25.563895 | BP4: 23.879412 | BQ4: 24.374632 | BR4: 24.539879 | BS4: 24.463566 | BT4: =+Cmg_Barra!BT4-Cmg_Cong!BT4 -> 24.596684 | BU4: 23.972983 | BV4: 23.872002 | BW4: 24.11063 | BX4: 24.482164 | BY4: 24.485502 | BZ4: 23.804341 | CA4: 23.121919 | CB4: 23.865533 | CC4: 23.334808 | CD4: 27.582272 | CE4: 22.704457 | CF4: 23.723757 | CG4: 28.059364 | CH4: 23.142498 | CI4: 24.010085 | CJ4: 23.978178 | CK4: 24.45795 | CL4: 25.905133 | CM4: 25.992535 | CN4: 25.551539 | CO4: 25.361753 | CP4: 25.992577 | CQ4: 24.366547 | CR4: 24.464125 | CS4: 24.224222 | CT4: 25.424916 | CU4: 25.444101 | CV4: 24.113664 | CW4: 24.399708 | CX4: 23.662753 | CY4: 24.392196 | CZ4: 23.997654 | DA4: 23.997654 | DB4: 24.016636 | DC4: 25.811164 | DD4: 25.929962 | DE4: 23.212776 | DF4: 21.587409 | DG4: 21.540057 | DH4: 21.750746 | DI4: 24.586129 | DJ4: 23.757193 | DK4: 23.716502 | DL4: 22.985819 | DM4: 27.408263 | DN4: 26.064321 | DO4: 26.06437 | DP4: 25.499007 | DQ4: 25.551539 | DR4: 23.865533 | DS4: 26.2241 | DT4: 23.972983 | DU4: 23.890562 | DV4: 24.109396 | DW4: 22.737271 | DX4: 22.722625 | DY4: 23.318814 | DZ4: 23.444305 | EA4: 22.515419 | EB4: 22.388917 | EC4: 23.952515 | ED4: 23.835285 | EE4: 23.786443 | EF4: 24.942608 | EG4: 22.538348 | EH4: 25.84528 | EI4: 24.211149 | EJ4: 26.712419 | EK4: 23.996152 | EL4: 23.996152 | EM4: 23.430912 | EN4: 24.528024 | EO4: 24.946697 | EP4: 24.946697 | EQ4: 25.316683 | ER4: 25.316192 | ES4: 23.667843 | ET4: 23.667843 | EU4: 25.440594 | EV4: 24.491637 | EW4: 23.364424 | EX4: 24.596684 | EY4: 24.596684 | EZ4: 25.913815 | FA4: 22.89672 | FB4: 25.361753 | FC4: 28.058967 | FD4: 22.7022 | FE4: 28.058967 | FF4: 25.315037 | FG4: 24.23284 | FH4: 25.170621 | FI4: 22.181572 | FJ4: 24.221569 | FK4: 23.491976 | FL4: 25.783523 | FM4: 25.655034 | FN4: 25.600764 | FO4: 24.221589 | FP4: 24.221569 | FQ4: 24.221581 | FR4: 26.442304 | FS4: 26.442304 | FT4: 25.342764 | FU4: 25.364833 | FV4: 25.275813 | FW4: 25.941635 | FX4: 23.757712 | FY4: 26.476473 | FZ4: 26.451704 | GA4: 24.359149 | GB4: 25.960381 | GC4: 24.34893 | GD4: 24.143233 | GE4: 24.09222 | GF4: 23.304329 | GG4: 22.397533 | GH4: 21.657714 | GI4: 21.729007 | GJ4: 24.132034 | GK4: 26.185841
B5: 43431.042 | C5: 23.903665 | D5: 23.933325 | E5: 23.921452 | F5: 23.903641 | G5: 24.334817 | H5: 25.993092 | I5: 26.078277 | J5: 26.033219 | K5: 24.916236 | L5: 23.995712 | M5: 25.746298 | N5: 25.213578 | O5: 24.23517 | P5: 26.043373 | Q5: 24.444318 | R5: 23.41454 | S5: 23.446686 | T5: 23.995322 | U5: 24.21034 | V5: 23.938726 | W5: 23.872175 | X5: 26.631904 | Y5: 23.042424 | Z5: 24.898164 | AA5: 24.214269 | AB5: 22.462636 | AC5: 23.793941 | AD5: 23.950599 | AE5: 22.594041 | AF5: 26.156217 | AG5: 24.055649 | AH5: 23.246685 | AI5: 23.332591 | AJ5: 25.919491 | AK5: 22.620606 | AL5: 21.139694 | AM5: 25.107215 | AN5: 24.595523 | AO5: 25.226474 | AP5: 24.283147 | AQ5: 23.394824 | AR5: 24.641804 | AS5: 24.00906 | AT5: 24.214455 | AU5: 24.082085 | AV5: 24.064177 | AW5: 24.09184 | AX5: 24.0488 | AY5: 25.966067 | AZ5: 26.007897 | BA5: 25.965866 | BB5: 25.965931 | BC5: 22.267801 | BD5: 24.270084 | BE5: 24.265742 | BF5: 25.586363 | BG5: 22.598227 | BH5: 22.598227 | BI5: 24.561637 | BJ5: 23.072897 | BK5: 24.622518 | BL5: 24.861965 | BM5: 24.861965 | BN5: 24.954352 | BO5: 25.727208 | BP5: 23.915248 | BQ5: 24.661832 | BR5: 24.638329 | BS5: 24.567173 | BT5: =+Cmg_Barra!BT5-Cmg_Cong!BT5 -> 24.622518 | BU5: 24.064177 | BV5: 23.962952 | BW5: 24.129193 | BX5: 24.516913 | BY5: 24.520176 | BZ5: 23.868358 | CA5: 23.148372 | CB5: 23.938726 | CC5: 23.541861 | CD5: 27.589963 | CE5: 22.734982 | CF5: 23.935434 | CG5: 28.23589 | CH5: 23.301683 | CI5: 24.072894 | CJ5: 24.036594 | CK5: 24.81549 | CL5: 26.068887 | CM5: 26.156313 | CN5: 25.713555 | CO5: 25.520731 | CP5: 26.156356 | CQ5: 24.765322 | CR5: 24.861965 | CS5: 24.296854 | CT5: 25.574351 | CU5: 25.593565 | CV5: 24.21446 | CW5: 24.44599 | CX5: 23.704977 | CY5: 24.439255 | CZ5: 24.09184 | DA5: 24.09184 | DB5: 24.085129 | DC5: 25.969704 | DD5: 26.084098 | DE5: 23.352343 | DF5: 21.644064 | DG5: 21.59659 | DH5: 21.793225 | DI5: 24.748069 | DJ5: 23.825835 | DK5: 23.786217 | DL5: 23.117996 | DM5: 27.580692 | DN5: 26.23668 | DO5: 26.236729 | DP5: 25.659582 | DQ5: 25.713555 | DR5: 23.938726 | DS5: 26.17082 | DT5: 24.064177 | DU5: 23.981453 | DV5: 24.17424 | DW5: 22.795625 | DX5: 22.783035 | DY5: 23.414941 | DZ5: 23.450842 | EA5: 22.567614 | EB5: 22.436852 | EC5: 24.002945 | ED5: 23.890762 | EE5: 23.844025 | EF5: 24.971144 | EG5: 22.570845 | EH5: 25.797873 | EI5: 24.286654 | EJ5: 26.64624 | EK5: 24.214455 | EL5: 24.214455 | EM5: 23.525932 | EN5: 24.671097 | EO5: 24.954352 | EP5: 24.954352 | EQ5: 25.471291 | ER5: 25.470798 | ES5: 23.780123 | ET5: 23.780123 | EU5: 25.59186 | EV5: 24.593694 | EW5: 23.401741 | EX5: 24.622518 | EY5: 24.622518 | EZ5: 26.077676 | FA5: 23.034774 | FB5: 25.520731 | FC5: 28.235491 | FD5: 22.848703 | FE5: 28.235491 | FF5: 25.46964 | FG5: 24.314112 | FH5: 25.332825 | FI5: 22.227217 | FJ5: 24.291342 | FK5: 23.633469 | FL5: 25.952711 | FM5: 25.820522 | FN5: 25.765354 | FO5: 24.291362 | FP5: 24.291342 | FQ5: 24.291355 | FR5: 26.32403 | FS5: 26.32403 | FT5: 25.291738 | FU5: 25.313586 | FV5: 25.224507 | FW5: 25.891931 | FX5: 23.804189 | FY5: 26.643462 | FZ5: 26.620068 | GA5: 24.368722 | GB5: 26.140053 | GC5: 24.397796 | GD5: 24.212826 | GE5: 24.161663 | GF5: 23.349842 | GG5: 22.512588 | GH5: 21.697895 | GI5: 21.770111 | GJ5: 24.209609 | GK5: 26.133046
